Workbook
Name __bookmark_1: #REF!
Name _bdm.029d27569d8f4137b38391c1866e0ecf.edm: #REF!
Name _I1: #REF!
Name _I10: #REF!
Name _I11: #REF!
Name _I12: #REF!
Name _I13: #REF!
Name _I14: #REF!
Name _I15: #REF!
Name _I16: #REF!
Name _I2: #REF!
Name _I3: #REF!
Name _I4: #REF!
Name _I5: #REF!
Name _I6: #REF!
Name _I7: #REF!
Name _I8: #REF!
Name _I9: #REF!
Name _P1: #REF!
Name _P2: #REF!
Name _P3: #REF!
Name _P4: #REF!
Name _P5: #REF!
Name _P6: #REF!
Name _RA9: #REF!
Name _RJ1: #REF!
Name _St1: #REF!
Name _St2: #REF!
Name _St3: #REF!
Name _St4: #REF!
Name _St5: #REF!
Name A: {0.1;0;0.382758620689655;0;0;0;0.258620689655172;0;0.258620689655172}
Name A: {0.1;0;0.382758620689655;0;0;0;0.258620689655172;0;0.258620689655172}
Name A: {0.1;0;0.382758620689655;0;0;0;0.258620689655172;0;0.258620689655172}
Name accounts: #REF!
Name adpt_ext_exp: #REF!
Name adpt_hdct_data: #REF!
Name AP: #REF!
Name AR: #REF!
Name AssumeSuccess: #REF!
Name AtlasReport: #REF!
Name AtlasReport_1: #REF!
Name AtlasReport_2: #REF!
Name BDCustom_OSProd1: 0
Name BDCustom_OSProd2: 1
Name BDCustom_OSProd3: 2
Name BDCustom_OSProd4: 3
Name BDCustom_P1: #REF!
Name BDCustom_P3: #REF!
Name BDEnabler: 0
Name BDScen_Prog1: #REF!
Name BDScen_Prog2: #REF!
Name Benefits: 350
Name Biophysics: #REF!
Name BMS: #REF!
Name BS: [12]Summary!$AA$11
Name BS: [13]Summary!$AA$11
Name Case: #REF!
Name Category: [12]Lists!$D$6:$D$7
Name Category: [13]Lists!$D$6:$D$7

Sheet WFP Details - 2026
A1: Temp Job ID | B1: Function | C1: Department | D1: Requestor / Manager | E1: Employee Type | F1: Level | G1: Title | H1: Location | I1: Functional Priority | J1: Corp. Priority | K1: Target Start Dt | L1: Recruiting Status | M1: Recruiter | N1: Hired Name | O1: HiBob ID | P1: Asset | Q1: Key Capability | R1: Catalyst for Growth (business rationale, key deliverables, etc.) | S1: Milestone / Trigger for Hire | T1: Talent Assessment | U1: Horizon 1 | V1: Tradeoff? | W1: FP&A (CM - Level) | X1: FP&A (CM - Timing) | Y1: FP&A (Note) | Z1: FP&A (255 Approved FTEs) | AA1: FP&A (Dept) | AB1: FP&A (Dept Tie Out) | AC1: FP&A (FTE Name) | AD1: FP&A (Level) | AE1: FP&A (Title) | AF1: FP&A (Hire Date) | AG1: Notes
A2: 1002 | B2: Communications | C2: 930 Communications | D2: Tassos Gianakakos | E2: FTE | F2: 09 - C-Suite | G2: Chief Communications Officer | H2: SSF | K2: 2024 Q3 | L2: Hired | N2: HIRED: Emily Faucette | O2: 10019 | P2: UA | Q2: Communications Leader | W2: 1. In line with Budget | X2: 1. In line with Budget | Y2: Included In Budget (Current FTE) | Z2: x | AA2: =_xlfn.XLOOKUP($A2,'2026 Approved Budget'!$B:$B,'2026 Approved Budget'!C:C) -> 930 Communications | AB2: OK | AC2: =_xlfn.XLOOKUP($A2,'2026 Approved Budget'!$B:$B,'2026 Approved Budget'!D:D) -> Emily Faucette | AD2: =_xlfn.XLOOKUP($A2,'2026 Approved Budget'!$B:$B,'2026 Approved Budget'!E:E) -> 10. C-Suite | AE2: =_xlfn.XLOOKUP($A2,'2026 Approved Budget'!$B:$B,'2026 Approved Budget'!F:F) -> Chief Communications Officer | AF2: =_xlfn.XLOOKUP($A2,'2026 Approved Budget'!$B:$B,'2026 Approved Budget'!H:H) -> 45488
A3: 1003 | B3: Communications | C3: 930 Communications | D3: Emily Faucette | E3: FTE | F3: 07 - Exec. Director | G3: Executive Director, Corporate Communications | H3: PNJ | K3: 2025 Q3 | L3: Hired | M3: Yen | N3: HIRED: Michael Bachner | O3: 10265 | P3: UA | Q3: External Communications (scenario planning, writing, media and website strategy to support data read outs, pipeline developments and corporate milestons) | R3: Pipeline introduction | S3: EC levergae hire to support pipeline introduction and upcoming data readouts | T3: Experienced Leader with proven track record who can hit the ground running, set strategy, mobilize resources and execute directly as needed. Must be willing (and motivated) to roll up sleeves and do the work. | W3: 1. In line with Budget | X3: 1. In line with Budget | Y3: Included In Budget (Current FTE) | Z3: x | AA3: =_xlfn.XLOOKUP($A3,'2026 Approved Budget'!$B:$B,'2026 Approved Budget'!C:C) -> 930 Communications | AB3: OK | AC3: =_xlfn.XLOOKUP($A3,'2026 Approved Budget'!$B:$B,'2026 Approved Budget'!D:D) -> Michael Bachner | AD3: =_xlfn.XLOOKUP($A3,'2026 Approved Budget'!$B:$B,'2026 Approved Budget'!E:E) -> 07. Exec. Director | AE3: =_xlfn.XLOOKUP($A3,'2026 Approved Budget'!$B:$B,'2026 Approved Budget'!F:F) -> Executive Director, External Communications | AF3: =_xlfn.XLOOKUP($A3,'2026 Approved Budget'!$B:$B,'2026 Approved Budget'!H:H) -> 45894
A4: 1004 | B4: Communications | C4: 930 Communications | D4: Emily Faucette | E4: FTE | F4: 07 - Exec. Director | G4: Exec Director, Internal Communication | H4: SSF | I4: 1 | K4: 2026 Q2 | L4: Open | M4: Yen | P4: UA | Q4: Employee communications roadmap to drive internal engagement, connectivity and re-recruitment across sites, partner with on Employer Brand, partner with P&C and IT on intranet startegy | R4: As company grows above 100 across 3 locations, increasinly important to have a seasoned, strategic internal communication expert to build a well thought out plan, including the resources to execute | S4: Pipeline introduction and upcoming data readouts | T4: Experienced Leader with proven track record who can hit the ground running, set strategy, mobilize resources and execute directly as needed. Must be willing (and motivated) to roll up sleeves and do the work. | W4: 3. Upgrade | X4: 2. Delayed | Y4: Included In Budget (Open Role) | Z4: x | AA4: =_xlfn.XLOOKUP($A4,'2026 Approved Budget'!$B:$B,'2026 Approved Budget'!C:C) -> 930 Communications | AB4: OK | AC4: =_xlfn.XLOOKUP($A4,'2026 Approved Budget'!$B:$B,'2026 Approved Budget'!D:D) -> CW: Meredith Kiernan (Convert to FTE Q1 26) | AD4: =_xlfn.XLOOKUP($A4,'2026 Approved Budget'!$B:$B,'2026 Approved Budget'!E:E) -> 06. Sr. Director | AE4: =_xlfn.XLOOKUP($A4,'2026 Approved Budget'!$B:$B,'2026 Approved Budget'!F:F) -> Senior Director, Internal Communication | AF4: =_xlfn.XLOOKUP($A4,'2026 Approved Budget'!$B:$B,'2026 Approved Budget'!H:H) -> 46096
A5: 5001 | B5: Communications | C5: 930 Communications | D5: Emily Faucette | E5: FTE | F5: 06 - Sr. Director | G5: KardiPro Internal and External Communications | H5: Chicago | I5: 2 | K5: 2026 Q1 | L5: Open | M5: Steven | N5: N/A | P5: UA | Q5: As the company launches the OKORO Heart Study and introduces Prolaio publically, we need to have a dedicated communications resource based in Chicago to oversee external communications (press releases, media outreach), partner with marketing on website and social media and develop a cohesive internal communications strategy to connect the Prolaians to each other and Kardigan as appropriate. | R5: Company growth, OKORO study launch, increased external presence and ongoing need to connect Kardigan and Prolaio people and stories as appropriate to drive each business forward. | S5: Kardigan acquiaition, OKORO study launch, first ever ublic presence beyond customer outreach | T5: Experienced Communications leader with proven track record who can hit the ground running, set strategy, mobilize resources and execute directly as needed. Must be willing (and motivated) to roll up sleeves and do the work. Health Tech experience a plus | W5: 1. In line with Budget | X5: 1. In line with Budget | Y5: Included In Budget (Open Role) | Z5: x | AA5: =_xlfn.XLOOKUP($A5,'2026 Approved Budget'!$B:$B,'2026 Approved Budget'!C:C) -> 930 Communications | AB5: OK | AC5: =_xlfn.XLOOKUP($A5,'2026 Approved Budget'!$B:$B,'2026 Approved Budget'!D:D) -> N/A | AD5: =_xlfn.XLOOKUP($A5,'2026 Approved Budget'!$B:$B,'2026 Approved Budget'!E:E) -> 06. Sr. Director | AE5: =_xlfn.XLOOKUP($A5,'2026 Approved Budget'!$B:$B,'2026 Approved Budget'!F:F) -> KardiPro Internal and External Communications | AF5: =_xlfn.XLOOKUP($A5,'2026 Approved Budget'!$B:$B,'2026 Approved Budget'!H:H) -> 46096
A6: 1310 | B6: Development | C6: 205 Executive Development | D6: Tassos Gianakakos | E6: FTE | F6: 09 - C-Suite | G6: CMO and Co-Founder | H6: PNJ | K6: 2024 Q1 | L6: Hired | N6: HIRED: Jay Edelberg | O6: 10002 | P6: UA | Q6: Lead Development Org | W6: 1. In line with Budget | X6: 1. In line with Budget | Y6: Included In Budget (Current FTE) | Z6: x | AA6: =_xlfn.XLOOKUP($A6,'2026 Approved Budget'!$B:$B,'2026 Approved Budget'!C:C) -> 205 Executive Development | AB6: OK | AC6: =_xlfn.XLOOKUP($A6,'2026 Approved Budget'!$B:$B,'2026 Approved Budget'!D:D) -> Jay Edelberg | AD6: =_xlfn.XLOOKUP($A6,'2026 Approved Budget'!$B:$B,'2026 Approved Budget'!E:E) -> 10. C-Suite | AE6: =_xlfn.XLOOKUP($A6,'2026 Approved Budget'!$B:$B,'2026 Approved Budget'!F:F) -> Chief Medical Officer | AF6: =_xlfn.XLOOKUP($A6,'2026 Approved Budget'!$B:$B,'2026 Approved Budget'!H:H) -> 45156
A7: 1068 | B7: Development | C7: 205 Executive Development | D7: Jay Edelberg | E7: FTE | F7: 01 - Below Manager | G7: Senior Executive Assistant | H7: SSF | K7: 2024 Q3 | L7: HIred | N7: HIRED: Jen Yu | O7: 10070 | P7: UA | Q7: Executive assistant - Dev and Quality | W7: 1. In line with Budget | X7: 1. In line with Budget | Y7: Included In Budget (Current FTE) | Z7: x | AA7: =_xlfn.XLOOKUP($A7,'2026 Approved Budget'!$B:$B,'2026 Approved Budget'!C:C) -> 205 Executive Development | AB7: OK | AC7: =_xlfn.XLOOKUP($A7,'2026 Approved Budget'!$B:$B,'2026 Approved Budget'!D:D) -> Jen Yu | AD7: =_xlfn.XLOOKUP($A7,'2026 Approved Budget'!$B:$B,'2026 Approved Budget'!E:E) -> 01. IC / Coordinator | AE7: =_xlfn.XLOOKUP($A7,'2026 Approved Budget'!$B:$B,'2026 Approved Budget'!F:F) -> Executive Assistant | AF7: =_xlfn.XLOOKUP($A7,'2026 Approved Budget'!$B:$B,'2026 Approved Budget'!H:H) -> 45558
A8: 5395 | B8: Development | C8: 205 Executive Development | D8: Jaclyn Patterson | E8: TG | F8: 01 - Below Manager | G8: Senior Executive Assistant | H8: PNJ | K8: 2026 Q1 | L8: Hired | M8: Kim | N8: HIRED: Nichole Mirisis-Franks | P8: UA | Q8: Executive assistant - Dev Ops and GPH's | W8: 4. Incremental Request | X8: 4. Incremental Request | Y8: Incremental Request | AA8: =_xlfn.XLOOKUP($A8,'2026 Approved Budget'!$B:$B,'2026 Approved Budget'!C:C) -> #N/A | AB8: Confirm w/ P&C | AC8: =_xlfn.XLOOKUP($A8,'2026 Approved Budget'!$B:$B,'2026 Approved Budget'!D:D) -> #N/A | AD8: =_xlfn.XLOOKUP($A8,'2026 Approved Budget'!$B:$B,'2026 Approved Budget'!E:E) -> #N/A | AE8: =_xlfn.XLOOKUP($A8,'2026 Approved Budget'!$B:$B,'2026 Approved Budget'!F:F) -> #N/A | AF8: =_xlfn.XLOOKUP($A8,'2026 Approved Budget'!$B:$B,'2026 Approved Budget'!H:H) -> #N/A | AG8: OOBR
A9: 5045 | B9: Development | C9: 215 Clinical Development | D9: Jay Edelberg | E9: FTE | F9: 08 - VP | G9: VP, Clinical Development | H9: PNJ | I9: 1 | J9: Program | K9: 2026 Q2 | M9: Linda | P9: ATA | Q9: Doctorate degree; Clinical oversight of Combination strategy & trial execution, combination strategy CDP development | R9: Development of combination strategy clinical trial program | S9: AVC data @24 weeks in ATA-301 & PoM for KAR-141; Research ACLY data | T9: Experienced Leader | U9: 02 - Data Trigger | W9: 2. Downgrade | X9: 1. In line with Budget | Y9: Included In Budget (Open Role) | Z9: x | AA9: =_xlfn.XLOOKUP($A9,'2026 Approved Budget'!$B:$B,'2026 Approved Budget'!C:C) -> 215 Clinical Development | AB9: OK | AC9: =_xlfn.XLOOKUP($A9,'2026 Approved Budget'!$B:$B,'2026 Approved Budget'!D:D) -> TBD | AD9: =_xlfn.XLOOKUP($A9,'2026 Approved Budget'!$B:$B,'2026 Approved Budget'!E:E) -> 07. Exec. Director | AE9: =_xlfn.XLOOKUP($A9,'2026 Approved Budget'!$B:$B,'2026 Approved Budget'!F:F) -> Executive Director, Clinical Development Lead | AF9: =_xlfn.XLOOKUP($A9,'2026 Approved Budget'!$B:$B,'2026 Approved Budget'!H:H) -> 46188 | AG9: accelerate to Q1 (open rec now)
A10: 1059 | B10: Development | C10: 208 Early Development | D10: Jay Edelberg | E10: FTE | F10: 08 - VP | G10: Vice President, Early Development | H10: PNJ | K10: 2024 Q4 | L10: Hired | N10: HIRED: Yehuda Cohen | O10: 10089 | P10: ATA-TLA-Dani | Q10: Translational Medicine | T10: Experienced Leader | W10: 1. In line with Budget | X10: 1. In line with Budget | Y10: Included In Budget (Current FTE) | Z10: x | AA10: =_xlfn.XLOOKUP($A10,'2026 Approved Budget'!$B:$B,'2026 Approved Budget'!C:C) -> 208 Early Development | AB10: OK | AC10: =_xlfn.XLOOKUP($A10,'2026 Approved Budget'!$B:$B,'2026 Approved Budget'!D:D) -> Yehuda Cohen | AD10: =_xlfn.XLOOKUP($A10,'2026 Approved Budget'!$B:$B,'2026 Approved Budget'!E:E) -> 08. VP | AE10: =_xlfn.XLOOKUP($A10,'2026 Approved Budget'!$B:$B,'2026 Approved Budget'!F:F) -> VP, Head of Early Clinical | AF10: =_xlfn.XLOOKUP($A10,'2026 Approved Budget'!$B:$B,'2026 Approved Budget'!H:H) -> 45600
A11: 1058 | B11: Development | C11: 208 Early Development | D11: Yehuda Cohen | E11: FTE | F11: 06 - Sr. Director | G11: Senior Director, Biomarkers | H11: PNJ | K11: 2025 Q2 | L11: Hired | N11: HIRED: Philippe Coslet | O11: 10223 | P11: ATA-TLA-Dani | Q11: Biomarkers | T11: Experienced Leader | W11: 3. Upgrade | X11: 1. In line with Budget | Y11: Included In Budget (Current FTE) | Z11: x | AA11: =_xlfn.XLOOKUP($A11,'2026 Approved Budget'!$B:$B,'2026 Approved Budget'!C:C) -> 208 Early Development | AB11: OK | AC11: =_xlfn.XLOOKUP($A11,'2026 Approved Budget'!$B:$B,'2026 Approved Budget'!D:D) -> Philippe Costet | AD11: =_xlfn.XLOOKUP($A11,'2026 Approved Budget'!$B:$B,'2026 Approved Budget'!E:E) -> 05. Director | AE11: =_xlfn.XLOOKUP($A11,'2026 Approved Budget'!$B:$B,'2026 Approved Budget'!F:F) -> AD / Director, Biomarkers | AF11: =_xlfn.XLOOKUP($A11,'2026 Approved Budget'!$B:$B,'2026 Approved Budget'!H:H) -> 45804
A12: 1296 | B12: Development | C12: 235 Regulatory | D12: Stu Heminway | E12: FTE | F12: 06 - Sr. Director | G12: Senior Director, Regulatory Operations | H12: SSF | I12: 2 | J12: Program | K12: 2026 Q1 | M12: Yen | P12: ATA-TLA | Q12: Regulatory Operations | S12: NDA Submission leadership/infrastructure/vendors for Filing Teams | U12: 03 - NDA Submission | V12: Keep | W12: 1. In line with Budget | X12: 1. In line with Budget | Y12: Included In Budget (Open Role) | Z12: x | AA12: =_xlfn.XLOOKUP($A12,'2026 Approved Budget'!$B:$B,'2026 Approved Budget'!C:C) -> 235 Regulatory | AB12: OK | AC12: =_xlfn.XLOOKUP($A12,'2026 Approved Budget'!$B:$B,'2026 Approved Budget'!D:D) -> TBD | AD12: =_xlfn.XLOOKUP($A12,'2026 Approved Budget'!$B:$B,'2026 Approved Budget'!E:E) -> 06. Sr. Director | AE12: =_xlfn.XLOOKUP($A12,'2026 Approved Budget'!$B:$B,'2026 Approved Budget'!F:F) -> Senior Director, Regulatory Operations | AF12: =_xlfn.XLOOKUP($A12,'2026 Approved Budget'!$B:$B,'2026 Approved Budget'!H:H) -> 46096 | AG12: most critical 2026 hire
A13: 1355 | B13: Development | C13: 210 Clinical Operations | D13: Jay Edelberg | E13: FTE | F13: 08 - VP | G13: Senior Vice President, Development Operations and Biometrics | H13: PNJ | K13: 2025 Q4 | L13: Hired | N13: HIRED: Jaclyn Patterson | O13: 10275 | P13: UA | T13: Experienced Leader | W13: 1. In line with Budget | X13: 1. In line with Budget | Y13: Included In Budget (Current FTE) | Z13: x | AA13: =_xlfn.XLOOKUP($A13,'2026 Approved Budget'!$B:$B,'2026 Approved Budget'!C:C) -> 210 Clinical Operations | AB13: OK | AC13: =_xlfn.XLOOKUP($A13,'2026 Approved Budget'!$B:$B,'2026 Approved Budget'!D:D) -> Jaclyn Patterson | AD13: =_xlfn.XLOOKUP($A13,'2026 Approved Budget'!$B:$B,'2026 Approved Budget'!E:E) -> 08. VP | AE13: =_xlfn.XLOOKUP($A13,'2026 Approved Budget'!$B:$B,'2026 Approved Budget'!F:F) -> SVP, Development Operations | AF13: =_xlfn.XLOOKUP($A13,'2026 Approved Budget'!$B:$B,'2026 Approved Budget'!H:H) -> 45943
A14: 1372 | B14: Development | C14: 210 Clinical Operations | D14: Jaclyn Patterson | E14: FTE | F14: 07 - Exec. Director | G14: ED, Digital Health Technologies & AI Enablement | H14: PNJ | K14: 2026 Q1 | L14: Hired | M14: Kim | N14: HIRED: Rinol Alaj | O14: 10360 | P14: ATA-TLA-Dani | S14: Now | W14: 3. Upgrade | X14: 3. Accelerated | Y14: Included In Budget (Open Role) | Z14: x | AA14: =_xlfn.XLOOKUP($A14,'2026 Approved Budget'!$B:$B,'2026 Approved Budget'!C:C) -> 210 Clinical Operations | AB14: Confirm w/ P&C | AC14: =_xlfn.XLOOKUP($A14,'2026 Approved Budget'!$B:$B,'2026 Approved Budget'!D:D) -> TBD | AD14: =_xlfn.XLOOKUP($A14,'2026 Approved Budget'!$B:$B,'2026 Approved Budget'!E:E) -> 06. Sr. Director | AE14: =_xlfn.XLOOKUP($A14,'2026 Approved Budget'!$B:$B,'2026 Approved Budget'!F:F) -> ED, Digital Health Technologies & AI Enablement | AF14: =_xlfn.XLOOKUP($A14,'2026 Approved Budget'!$B:$B,'2026 Approved Budget'!H:H) -> 46280 | AG14: keep / key
A15: 1370 | B15: Development | C15: 210 Clinical Operations | D15: Jaclyn Patterson | E15: FTE | F15: 06 - Sr. Director | G15: Sr. Director, Clinical Ops Program Lead, Dani | H15: PNJ | K15: 2024 Q1 | L15: Hired | N15: HIRED: Brianne Leary | O15: 10004 | P15: Dani | U15: 01 - Data Readout | W15: 1. In line with Budget | X15: 1. In line with Budget | Y15: Included In Budget (Current FTE) | Z15: x | AA15: =_xlfn.XLOOKUP($A15,'2026 Approved Budget'!$B:$B,'2026 Approved Budget'!C:C) -> 210 Clinical Operations | AB15: OK | AC15: =_xlfn.XLOOKUP($A15,'2026 Approved Budget'!$B:$B,'2026 Approved Budget'!D:D) -> TBD | AD15: =_xlfn.XLOOKUP($A15,'2026 Approved Budget'!$B:$B,'2026 Approved Budget'!E:E) -> 06. Sr. Director | AE15: =_xlfn.XLOOKUP($A15,'2026 Approved Budget'!$B:$B,'2026 Approved Budget'!F:F) -> Clinical Ops Program Lead Dani | AF15: =_xlfn.XLOOKUP($A15,'2026 Approved Budget'!$B:$B,'2026 Approved Budget'!H:H) -> 46096
A16: 1040 | B16: Development | C16: 210 Clinical Operations | D16: Jaclyn Patterson | E16: FTE | F16: 06 - Sr. Director | G16: Sr. Director, Clinical Operations Program Lead, ATA | H16: PNJ | K16: 2026 Q1 | L16: Hired | M16: Kim | N16: HIRED: Sanjay Patel | O16: 10283 | P16: ATA | T16: Experienced Leader | W16: 1. In line with Budget | X16: 1. In line with Budget | Y16: Included In Budget (Current FTE) | Z16: x | AA16: =_xlfn.XLOOKUP($A16,'2026 Approved Budget'!$B:$B,'2026 Approved Budget'!C:C) -> 210 Clinical Operations | AB16: OK | AC16: =_xlfn.XLOOKUP($A16,'2026 Approved Budget'!$B:$B,'2026 Approved Budget'!D:D) -> Lisa Morello | AD16: =_xlfn.XLOOKUP($A16,'2026 Approved Budget'!$B:$B,'2026 Approved Budget'!E:E) -> 06. Sr. Director | AE16: =_xlfn.XLOOKUP($A16,'2026 Approved Budget'!$B:$B,'2026 Approved Budget'!F:F) -> Clinical Ops Program Lead ATA | AF16: =_xlfn.XLOOKUP($A16,'2026 Approved Budget'!$B:$B,'2026 Approved Budget'!H:H) -> 45943
A17: 1036 | B17: Development | C17: 210 Clinical Operations | D17: Jaclyn Patterson | E17: FTE | F17: 05 - Director | G17: Sr. Director, Clinical Operations Program Lead, TLA | H17: SSF | K17: 2025 Q1 | L17: Hired | M17: Yen | N17: HIRED: Caroline Cooper | O17: 10125 | P17: TLA | Q17: Program Management. BACKFILL: Jim Marco | W17: 1. In line with Budget | X17: 1. In line with Budget | Y17: Included In Budget (Current FTE) | Z17: x | AA17: =_xlfn.XLOOKUP($A17,'2026 Approved Budget'!$B:$B,'2026 Approved Budget'!C:C) -> 210 Clinical Operations | AB17: OK | AC17: =_xlfn.XLOOKUP($A17,'2026 Approved Budget'!$B:$B,'2026 Approved Budget'!D:D) -> Caroline Cooper | AD17: =_xlfn.XLOOKUP($A17,'2026 Approved Budget'!$B:$B,'2026 Approved Budget'!E:E) -> 05. Director | AE17: =_xlfn.XLOOKUP($A17,'2026 Approved Budget'!$B:$B,'2026 Approved Budget'!F:F) -> Director, Clinical Ops Program Lead, TLA | AF17: =_xlfn.XLOOKUP($A17,'2026 Approved Budget'!$B:$B,'2026 Approved Budget'!H:H) -> 45663
A18: 1032 | B18: Development | C18: 210 Clinical Operations | D18: Brianne Leary | E18: FTE | F18: 05 - Director | G18: Director, Development Business Operations | H18: SSF | K18: 2025 Q2 | L18: Hired | N18: HIRED: Andrea Koh | O18: 10204 | P18: Dani | Q18: Clinical Contracts (CRO/vendors/sites) | T18: Experienced Leader | W18: 1. In line with Budget | X18: 1. In line with Budget | Y18: Included In Budget (Current FTE) | Z18: x | AA18: =_xlfn.XLOOKUP($A18,'2026 Approved Budget'!$B:$B,'2026 Approved Budget'!C:C) -> 210 Clinical Operations | AB18: OK | AC18: =_xlfn.XLOOKUP($A18,'2026 Approved Budget'!$B:$B,'2026 Approved Budget'!D:D) -> Andrea Koh | AD18: =_xlfn.XLOOKUP($A18,'2026 Approved Budget'!$B:$B,'2026 Approved Budget'!E:E) -> 05. Director | AE18: =_xlfn.XLOOKUP($A18,'2026 Approved Budget'!$B:$B,'2026 Approved Budget'!F:F) -> Director, Dev Business Operations | AF18: =_xlfn.XLOOKUP($A18,'2026 Approved Budget'!$B:$B,'2026 Approved Budget'!H:H) -> 45775
A19: 1044 | B19: Development | C19: 210 Clinical Operations | D19: Brianne Leary | E19: FTE | F19: 04 - Assoc. Director | G19: Associate Director, Clinical Program Lead | H19: SSF | K19: 2024 Q3 | L19: Hired | N19: HIRED: Mindy Worsham | O19: 10079 | P19: UA | Q19: Program Management; Phase 3 planning | T19: Emerging Leader | W19: 1. In line with Budget | X19: 1. In line with Budget | Y19: Included In Budget (Current FTE) | Z19: x | AA19: =_xlfn.XLOOKUP($A19,'2026 Approved Budget'!$B:$B,'2026 Approved Budget'!C:C) -> 210 Clinical Operations | AB19: OK | AC19: =_xlfn.XLOOKUP($A19,'2026 Approved Budget'!$B:$B,'2026 Approved Budget'!D:D) -> Mindy Worsham | AD19: =_xlfn.XLOOKUP($A19,'2026 Approved Budget'!$B:$B,'2026 Approved Budget'!E:E) -> 04. AD / Staff Scientist | AE19: =_xlfn.XLOOKUP($A19,'2026 Approved Budget'!$B:$B,'2026 Approved Budget'!F:F) -> Director, Clinical Operations Excellence | AF19: =_xlfn.XLOOKUP($A19,'2026 Approved Budget'!$B:$B,'2026 Approved Budget'!H:H) -> 45558
A20: 1039 | B20: Development | C20: 210 Clinical Operations | D20: Sanjay Patel | E20: FTE | F20: 04 - Assoc. Director | G20: Associate Director, Clinical Trial Lead | H20: SSF | K20: 2024 Q3 | L20: Hired | M20: Yen | N20: HIRED: Mandy Lin | O20: 10081 | P20: ATA | Q20: Clinical Trial Management | W20: 1. In line with Budget | X20: 1. In line with Budget | Y20: Included In Budget (Current FTE) | Z20: x | AA20: =_xlfn.XLOOKUP($A20,'2026 Approved Budget'!$B:$B,'2026 Approved Budget'!C:C) -> 210 Clinical Operations | AB20: OK | AC20: =_xlfn.XLOOKUP($A20,'2026 Approved Budget'!$B:$B,'2026 Approved Budget'!D:D) -> Mandy Lin | AD20: =_xlfn.XLOOKUP($A20,'2026 Approved Budget'!$B:$B,'2026 Approved Budget'!E:E) -> 04. AD / Staff Scientist | AE20: =_xlfn.XLOOKUP($A20,'2026 Approved Budget'!$B:$B,'2026 Approved Budget'!F:F) -> Clinical Trial Lead | AF20: =_xlfn.XLOOKUP($A20,'2026 Approved Budget'!$B:$B,'2026 Approved Budget'!H:H) -> 45558
A21: 1292 | B21: Development | C21: 210 Clinical Operations | D21: Caroline Cooper | E21: FTE | F21: 04 - Assoc. Director | G21: Associate Director, Clinical Trial Lead | H21: SSF | K21: 2024 Q4 | L21: Hired | N21: HIRED: Jody Dosanjh | O21: 10102 | P21: Dani | Q21: Clinical Trial Management | W21: 1. In line with Budget | X21: 1. In line with Budget | Y21: Included In Budget (Current FTE) | Z21: x | AA21: =_xlfn.XLOOKUP($A21,'2026 Approved Budget'!$B:$B,'2026 Approved Budget'!C:C) -> 210 Clinical Operations | AB21: OK | AC21: =_xlfn.XLOOKUP($A21,'2026 Approved Budget'!$B:$B,'2026 Approved Budget'!D:D) -> Jody Dosanjh | AD21: =_xlfn.XLOOKUP($A21,'2026 Approved Budget'!$B:$B,'2026 Approved Budget'!E:E) -> 04. AD / Staff Scientist | AE21: =_xlfn.XLOOKUP($A21,'2026 Approved Budget'!$B:$B,'2026 Approved Budget'!F:F) -> Clinical Trial Lead | AF21: =_xlfn.XLOOKUP($A21,'2026 Approved Budget'!$B:$B,'2026 Approved Budget'!H:H) -> 45628
A22: 1030 | B22: Development | C22: 210 Clinical Operations | D22: Caroline Cooper | E22: FTE | F22: 03 - Sr. Manager | G22: Senior Manager, Clinical Trial Lead | H22: PNJ | K22: 2024 Q2 | L22: Hired | N22: HIRED: Jessica Kim | O22: 10016 | P22: TLA | Q22: Clinical Trial Management. ION904 Clinical Trial Lead. | W22: 1. In line with Budget | X22: 1. In line with Budget | Y22: Included In Budget (Current FTE) | Z22: x | AA22: =_xlfn.XLOOKUP($A22,'2026 Approved Budget'!$B:$B,'2026 Approved Budget'!C:C) -> 210 Clinical Operations | AB22: OK | AC22: =_xlfn.XLOOKUP($A22,'2026 Approved Budget'!$B:$B,'2026 Approved Budget'!D:D) -> Jessica Kim | AD22: =_xlfn.XLOOKUP($A22,'2026 Approved Budget'!$B:$B,'2026 Approved Budget'!E:E) -> 03. Sr. Manager / Sr. Scientist | AE22: =_xlfn.XLOOKUP($A22,'2026 Approved Budget'!$B:$B,'2026 Approved Budget'!F:F) -> Clinical Trial Lead | AF22: =_xlfn.XLOOKUP($A22,'2026 Approved Budget'!$B:$B,'2026 Approved Budget'!H:H) -> 45467
A23: 1046 | B23: Development | C23: 210 Clinical Operations | D23: Sanjay Patel | E23: FTE | F23: 03 - Sr. Manager | G23: Senior Manager, Clinical Trial Lead | H23: SSF | K23: 2025 Q1 | L23: Hired | M23: Yen | N23: HIRED: Tiffany Shu | O23: 10127 | P23: ATA | Q23: Vendor Oversight (CPET, Prolaio, etc) | W23: 1. In line with Budget | X23: 1. In line with Budget | Y23: Included In Budget (Current FTE) | Z23: x | AA23: =_xlfn.XLOOKUP($A23,'2026 Approved Budget'!$B:$B,'2026 Approved Budget'!C:C) -> 210 Clinical Operations | AB23: OK | AC23: =_xlfn.XLOOKUP($A23,'2026 Approved Budget'!$B:$B,'2026 Approved Budget'!D:D) -> Tiffany Shu | AD23: =_xlfn.XLOOKUP($A23,'2026 Approved Budget'!$B:$B,'2026 Approved Budget'!E:E) -> 03. Sr. Manager / Sr. Scientist | AE23: =_xlfn.XLOOKUP($A23,'2026 Approved Budget'!$B:$B,'2026 Approved Budget'!F:F) -> Clinical Trial Manager | AF23: =_xlfn.XLOOKUP($A23,'2026 Approved Budget'!$B:$B,'2026 Approved Budget'!H:H) -> 45663
A24: 1037 | B24: Development | C24: 210 Clinical Operations | D24: Caroline Cooper | E24: FTE | F24: 03 - Sr. Manager | G24: Senior Manager, Clinical Trial Lead | H24: PNJ | K24: 2026 Q1 | L24: Hired | M24: Kim | N24: HIRED: Araceli Melgar | O24: 10358 | P24: TLA | T24: Emerging Leader | U24: 01 - Data Readout | W24: 2. Downgrade | X24: 1. In line with Budget | Y24: Included In Budget (Current FTE) | Z24: x | AA24: =_xlfn.XLOOKUP($A24,'2026 Approved Budget'!$B:$B,'2026 Approved Budget'!C:C) -> 210 Clinical Operations | AB24: OK | AC24: =_xlfn.XLOOKUP($A24,'2026 Approved Budget'!$B:$B,'2026 Approved Budget'!D:D) -> CW: Heather Fraser | AD24: =_xlfn.XLOOKUP($A24,'2026 Approved Budget'!$B:$B,'2026 Approved Budget'!E:E) -> 04. AD / Staff Scientist | AE24: =_xlfn.XLOOKUP($A24,'2026 Approved Budget'!$B:$B,'2026 Approved Budget'!F:F) -> Clinical Trial Lead | AF24: =_xlfn.XLOOKUP($A24,'2026 Approved Budget'!$B:$B,'2026 Approved Budget'!H:H) -> 46006
A25: 1056 | B25: Development | C25: 210 Clinical Operations | D25: Caroline Cooper | E25: FTE | F25: 01 - Below Manager | G25: Associate Manager, Clinical Site Operations | H25: SSF | K25: 2025 Q1 | L25: Hired | N25: HIRED: Rachel Day | O25: 10120 | P25: TLA | Q25: Site Monitoring & Performance. US ATA | W25: 1. In line with Budget | X25: 1. In line with Budget | Y25: Included In Budget (Current FTE) | Z25: x | AA25: =_xlfn.XLOOKUP($A25,'2026 Approved Budget'!$B:$B,'2026 Approved Budget'!C:C) -> 210 Clinical Operations | AB25: OK | AC25: =_xlfn.XLOOKUP($A25,'2026 Approved Budget'!$B:$B,'2026 Approved Budget'!D:D) -> Rachel Day | AD25: =_xlfn.XLOOKUP($A25,'2026 Approved Budget'!$B:$B,'2026 Approved Budget'!E:E) -> 01. IC / Coordinator | AE25: =_xlfn.XLOOKUP($A25,'2026 Approved Budget'!$B:$B,'2026 Approved Budget'!F:F) -> Associate Manager, Clinical Site Operations | AF25: =_xlfn.XLOOKUP($A25,'2026 Approved Budget'!$B:$B,'2026 Approved Budget'!H:H) -> 45663
A26: 1052 | B26: Development | C26: 210 Clinical Operations | D26: Mandy Lin | E26: FTE | F26: 01 - Below Manager | G26: Senior Clinical Trial Associate | H26: SSF | K26: 2025 Q2 | L26: Hired | M26: Yen | N26: HIRED: Vicky Ho | O26: 10157 | P26: ATA | Q26: Clinical project mgmt support | W26: 1. In line with Budget | X26: 1. In line with Budget | Y26: Included In Budget (Current FTE) | Z26: x | AA26: =_xlfn.XLOOKUP($A26,'2026 Approved Budget'!$B:$B,'2026 Approved Budget'!C:C) -> 210 Clinical Operations | AB26: OK | AC26: =_xlfn.XLOOKUP($A26,'2026 Approved Budget'!$B:$B,'2026 Approved Budget'!D:D) -> Vicky Ho | AD26: =_xlfn.XLOOKUP($A26,'2026 Approved Budget'!$B:$B,'2026 Approved Budget'!E:E) -> 01. IC / Coordinator | AE26: =_xlfn.XLOOKUP($A26,'2026 Approved Budget'!$B:$B,'2026 Approved Budget'!F:F) -> Sr. Clinical Trial Associate | AF26: =_xlfn.XLOOKUP($A26,'2026 Approved Budget'!$B:$B,'2026 Approved Budget'!H:H) -> 45831
A27: 1352 | B27: Development | C27: 210 Clinical Operations | D27: Brianne Leary | E27: CW | F27: 05 - Director | G27: Clinical Operations Lead, Early Development | H27: US Remote | K27: 2025 Q2 | L27: Hired - CW | N27: CW: Susan Szambelan | P27: UA | Q27: Clinical Trial Management | W27: N/A - CW | X27: N/A - CW | Y27: N/A (CW) | AA27: =_xlfn.XLOOKUP($A27,'2026 Approved Budget'!$B:$B,'2026 Approved Budget'!C:C) -> #N/A | AB27: N/A (CW) | AC27: =_xlfn.XLOOKUP($A27,'2026 Approved Budget'!$B:$B,'2026 Approved Budget'!D:D) -> #N/A | AD27: =_xlfn.XLOOKUP($A27,'2026 Approved Budget'!$B:$B,'2026 Approved Budget'!E:E) -> #N/A | AE27: =_xlfn.XLOOKUP($A27,'2026 Approved Budget'!$B:$B,'2026 Approved Budget'!F:F) -> #N/A | AF27: =_xlfn.XLOOKUP($A27,'2026 Approved Budget'!$B:$B,'2026 Approved Budget'!H:H) -> #N/A
A28: 1354 | B28: Development | C28: 210 Clinical Operations | D28: Brianne Leary | E28: CW | F28: 04 - Assoc. Director | G28: Sr. Consultant, eTMF | H28: US Remote | K28: 2025 Q2 | L28: Hired - CW | N28: CW: Katie Hoover | P28: UA | Q28: eTMF, Training | S28: Inspection Readiness Kick off | W28: N/A - CW | X28: N/A - CW | Y28: N/A (CW) | AA28: =_xlfn.XLOOKUP($A28,'2026 Approved Budget'!$B:$B,'2026 Approved Budget'!C:C) -> #N/A | AB28: N/A (CW) | AC28: =_xlfn.XLOOKUP($A28,'2026 Approved Budget'!$B:$B,'2026 Approved Budget'!D:D) -> #N/A | AD28: =_xlfn.XLOOKUP($A28,'2026 Approved Budget'!$B:$B,'2026 Approved Budget'!E:E) -> #N/A | AE28: =_xlfn.XLOOKUP($A28,'2026 Approved Budget'!$B:$B,'2026 Approved Budget'!F:F) -> #N/A | AF28: =_xlfn.XLOOKUP($A28,'2026 Approved Budget'!$B:$B,'2026 Approved Budget'!H:H) -> #N/A
A29: 1324 | B29: Development | C29: 210 Clinical Operations | D29: Caroline Cooper | E29: CW | F29: 03 - Sr. Manager | G29: Senior Manager, Clinical Site Operations | H29: SSF | K29: 2025 Q2 | L29: Hired - CW | N29: CW: Ali Zetter | P29: TLA | Q29: Site selection and initiation (feasibility, qualifications) and monitoring | W29: N/A - CW | X29: N/A - CW | Y29: N/A (CW) | AA29: =_xlfn.XLOOKUP($A29,'2026 Approved Budget'!$B:$B,'2026 Approved Budget'!C:C) -> #N/A | AB29: N/A (CW) | AC29: =_xlfn.XLOOKUP($A29,'2026 Approved Budget'!$B:$B,'2026 Approved Budget'!D:D) -> #N/A | AD29: =_xlfn.XLOOKUP($A29,'2026 Approved Budget'!$B:$B,'2026 Approved Budget'!E:E) -> #N/A | AE29: =_xlfn.XLOOKUP($A29,'2026 Approved Budget'!$B:$B,'2026 Approved Budget'!F:F) -> #N/A | AF29: =_xlfn.XLOOKUP($A29,'2026 Approved Budget'!$B:$B,'2026 Approved Budget'!H:H) -> #N/A
A30: 1325 | B30: Development | C30: 210 Clinical Operations | D30: Caroline Cooper | E30: CW | F30: 03 - Sr. Manager | G30: Senior Manager, Clinical Site Operations | H30: US Remote | K30: 2025 Q2 | L30: Hired - CW | N30: CW: Chris Page | P30: TLA | Q30: Site selection and initiation (feasibility, qualifications) and monitoring | W30: N/A - CW | X30: N/A - CW | Y30: N/A (CW) | AA30: =_xlfn.XLOOKUP($A30,'2026 Approved Budget'!$B:$B,'2026 Approved Budget'!C:C) -> #N/A | AB30: N/A (CW) | AC30: =_xlfn.XLOOKUP($A30,'2026 Approved Budget'!$B:$B,'2026 Approved Budget'!D:D) -> #N/A | AD30: =_xlfn.XLOOKUP($A30,'2026 Approved Budget'!$B:$B,'2026 Approved Budget'!E:E) -> #N/A | AE30: =_xlfn.XLOOKUP($A30,'2026 Approved Budget'!$B:$B,'2026 Approved Budget'!F:F) -> #N/A | AF30: =_xlfn.XLOOKUP($A30,'2026 Approved Budget'!$B:$B,'2026 Approved Budget'!H:H) -> #N/A
A31: 5047 | B31: Development | C31: 210 Clinical Operations | D31: Brianne Leary | E31: CW | F31: 03 - Sr. Manager | G31: Clinical Trial Lead | H31: US Remote | K31: 2025 Q4 | L31: Hired - CW | N31: CW: Jade Cao | P31: Dani | Q31: Dani program | W31: N/A - CW | X31: N/A - CW | Y31: N/A (CW) | AA31: =_xlfn.XLOOKUP($A31,'2026 Approved Budget'!$B:$B,'2026 Approved Budget'!C:C) -> #N/A | AB31: N/A (CW) | AC31: =_xlfn.XLOOKUP($A31,'2026 Approved Budget'!$B:$B,'2026 Approved Budget'!D:D) -> #N/A | AD31: =_xlfn.XLOOKUP($A31,'2026 Approved Budget'!$B:$B,'2026 Approved Budget'!E:E) -> #N/A | AE31: =_xlfn.XLOOKUP($A31,'2026 Approved Budget'!$B:$B,'2026 Approved Budget'!F:F) -> #N/A | AF31: =_xlfn.XLOOKUP($A31,'2026 Approved Budget'!$B:$B,'2026 Approved Budget'!H:H) -> #N/A
A32: 5097 | B32: Development | C32: 210 Clinical Operations | D32: Brianne Leary | E32: CW | F32: 02 - Manager | G32: Clinical Trial Manager | H32: US Remote | K32: 2025 Q2 | L32: Hired - CW | N32: CW: Jutta Durstewitz | P32: Dani | W32: N/A - Not in FP&A list | X32: N/A - Not in FP&A list | Y32: Not in FP&A list | AA32: =_xlfn.XLOOKUP($A32,'2026 Approved Budget'!$B:$B,'2026 Approved Budget'!C:C) -> #N/A | AB32: N/A (CW) | AC32: =_xlfn.XLOOKUP($A32,'2026 Approved Budget'!$B:$B,'2026 Approved Budget'!D:D) -> #N/A | AD32: =_xlfn.XLOOKUP($A32,'2026 Approved Budget'!$B:$B,'2026 Approved Budget'!E:E) -> #N/A | AE32: =_xlfn.XLOOKUP($A32,'2026 Approved Budget'!$B:$B,'2026 Approved Budget'!F:F) -> #N/A | AF32: =_xlfn.XLOOKUP($A32,'2026 Approved Budget'!$B:$B,'2026 Approved Budget'!H:H) -> #N/A
A33: 1336 | B33: Development | C33: 210 Clinical Operations | D33: Mindy Worsham | E33: CW | F33: 02 - Manager | G33: Clinical Trial Manager | H33: SSF | K33: 2025 Q3 | L33: Hired - CW | N33: CW: Anila Choudhry | P33: ATA | Q33: Clinical Trial Management | W33: N/A - CW | X33: N/A - CW | Y33: N/A (CW) | AA33: =_xlfn.XLOOKUP($A33,'2026 Approved Budget'!$B:$B,'2026 Approved Budget'!C:C) -> #N/A | AB33: N/A (CW) | AC33: =_xlfn.XLOOKUP($A33,'2026 Approved Budget'!$B:$B,'2026 Approved Budget'!D:D) -> #N/A | AD33: =_xlfn.XLOOKUP($A33,'2026 Approved Budget'!$B:$B,'2026 Approved Budget'!E:E) -> #N/A | AE33: =_xlfn.XLOOKUP($A33,'2026 Approved Budget'!$B:$B,'2026 Approved Budget'!F:F) -> #N/A | AF33: =_xlfn.XLOOKUP($A33,'2026 Approved Budget'!$B:$B,'2026 Approved Budget'!H:H) -> #N/A
A34: 1353 | B34: Development | C34: 210 Clinical Operations | D34: Jody Dosanjh | E34: CW | F34: 02 - Manager | G34: Sr. Clinical Trial Manager | H34: US Remote | K34: 2025 Q3 | L34: Hired - CW | N34: CW: Suzette Warren | P34: Dani | W34: N/A - CW | X34: N/A - CW | Y34: N/A (CW) | AA34: =_xlfn.XLOOKUP($A34,'2026 Approved Budget'!$B:$B,'2026 Approved Budget'!C:C) -> #N/A | AB34: N/A (CW) | AC34: =_xlfn.XLOOKUP($A34,'2026 Approved Budget'!$B:$B,'2026 Approved Budget'!D:D) -> #N/A | AD34: =_xlfn.XLOOKUP($A34,'2026 Approved Budget'!$B:$B,'2026 Approved Budget'!E:E) -> #N/A | AE34: =_xlfn.XLOOKUP($A34,'2026 Approved Budget'!$B:$B,'2026 Approved Budget'!F:F) -> #N/A | AF34: =_xlfn.XLOOKUP($A34,'2026 Approved Budget'!$B:$B,'2026 Approved Budget'!H:H) -> #N/A
A35: 1371 | B35: Development | C35: 210 Clinical Operations | D35: Mandy Lin | E35: CW | F35: 02 - Manager | G35: Clinical Trial Manager | H35: SSF | K35: 2025 Q3 | L35: Hired - CW | N35: CW: Mandeep Grewal | P35: ATA | S35: Now | W35: N/A - CW | X35: N/A - CW | Y35: N/A (CW) | AA35: =_xlfn.XLOOKUP($A35,'2026 Approved Budget'!$B:$B,'2026 Approved Budget'!C:C) -> #N/A | AB35: N/A (CW) | AC35: =_xlfn.XLOOKUP($A35,'2026 Approved Budget'!$B:$B,'2026 Approved Budget'!D:D) -> #N/A | AD35: =_xlfn.XLOOKUP($A35,'2026 Approved Budget'!$B:$B,'2026 Approved Budget'!E:E) -> #N/A | AE35: =_xlfn.XLOOKUP($A35,'2026 Approved Budget'!$B:$B,'2026 Approved Budget'!F:F) -> #N/A | AF35: =_xlfn.XLOOKUP($A35,'2026 Approved Budget'!$B:$B,'2026 Approved Budget'!H:H) -> #N/A
A36: 1054 | B36: Development | C36: 210 Clinical Operations | D36: Jessica Kim | E36: CW | F36: 01 - Below Manager | G36: Sr. Clinical Trial Associate | H36: US Remote | K36: 2024 Q4 | L36: Hired - CW | N36: CW: Miranda Rhudy | P36: TLA | Q36: Clinical project mgmt support | W36: N/A - CW | X36: N/A - CW | Y36: N/A (CW) | AA36: =_xlfn.XLOOKUP($A36,'2026 Approved Budget'!$B:$B,'2026 Approved Budget'!C:C) -> #N/A | AB36: N/A (CW) | AC36: =_xlfn.XLOOKUP($A36,'2026 Approved Budget'!$B:$B,'2026 Approved Budget'!D:D) -> #N/A | AD36: =_xlfn.XLOOKUP($A36,'2026 Approved Budget'!$B:$B,'2026 Approved Budget'!E:E) -> #N/A | AE36: =_xlfn.XLOOKUP($A36,'2026 Approved Budget'!$B:$B,'2026 Approved Budget'!F:F) -> #N/A | AF36: =_xlfn.XLOOKUP($A36,'2026 Approved Budget'!$B:$B,'2026 Approved Budget'!H:H) -> #N/A
A37: 1053 | B37: Development | C37: 210 Clinical Operations | D37: Brianne Leary | E37: CW | F37: 01 - Below Manager | G37: Sr. Clinical Trial Associate | H37: SSF | K37: 2025 Q3 | L37: Hired - CW | N37: CW: Karrin Huang | P37: Dani | Q37: Clinical project mgmt support | W37: N/A - CW | X37: N/A - CW | Y37: N/A (CW) | AA37: =_xlfn.XLOOKUP($A37,'2026 Approved Budget'!$B:$B,'2026 Approved Budget'!C:C) -> #N/A | AB37: N/A (CW) | AC37: =_xlfn.XLOOKUP($A37,'2026 Approved Budget'!$B:$B,'2026 Approved Budget'!D:D) -> #N/A | AD37: =_xlfn.XLOOKUP($A37,'2026 Approved Budget'!$B:$B,'2026 Approved Budget'!E:E) -> #N/A | AE37: =_xlfn.XLOOKUP($A37,'2026 Approved Budget'!$B:$B,'2026 Approved Budget'!F:F) -> #N/A | AF37: =_xlfn.XLOOKUP($A37,'2026 Approved Budget'!$B:$B,'2026 Approved Budget'!H:H) -> #N/A
A38: 5360 | B38: Development | C38: 215 Clinical Development | D38: Jay Edelberg | E38: FTE | F38: 08 - VP | G38: VP, Clinical Development | H38: PNJ | I38: 3 | J38: Program | K38: 2026 Q1 | M38: Linda | P38: TLA | Q38: TBD | W38: 1. In line with Budget | X38: 3. Accelerated | Y38: Included In Budget (Open Role) | Z38: x | AA38: =_xlfn.XLOOKUP($A38,'2026 Approved Budget'!$B:$B,'2026 Approved Budget'!C:C) -> 205 Executive Development | AB38: Confirm w/ P&C | AC38: =_xlfn.XLOOKUP($A38,'2026 Approved Budget'!$B:$B,'2026 Approved Budget'!D:D) -> TBD | AD38: =_xlfn.XLOOKUP($A38,'2026 Approved Budget'!$B:$B,'2026 Approved Budget'!E:E) -> 08. VP | AE38: =_xlfn.XLOOKUP($A38,'2026 Approved Budget'!$B:$B,'2026 Approved Budget'!F:F) -> SVP, Clinical Development | AF38: =_xlfn.XLOOKUP($A38,'2026 Approved Budget'!$B:$B,'2026 Approved Budget'!H:H) -> 46371 | AG38: keep / key
A39: 5384 | B39: Development | C39: 210 Clinical Operations | D39: Jaclyn Patterson | E39: FTE | F39: 08 - VP | G39: Head of Development Services | H39: PNJ | I39: 4 | J39: Program | K39: 2026 Q1 | L39: Open | M39: Kim | P39: UA | W39: 3. Upgrade | X39: 3. Accelerated | Y39: Included In Budget (Open Role) | Z39: x | AA39: =_xlfn.XLOOKUP($A39,'2026 Approved Budget'!$B:$B,'2026 Approved Budget'!C:C) -> 901 Executive G&A | AB39: Confirm w/ P&C | AC39: =_xlfn.XLOOKUP($A39,'2026 Approved Budget'!$B:$B,'2026 Approved Budget'!D:D) -> TBD | AD39: =_xlfn.XLOOKUP($A39,'2026 Approved Budget'!$B:$B,'2026 Approved Budget'!E:E) -> 05. Director | AE39: =_xlfn.XLOOKUP($A39,'2026 Approved Budget'!$B:$B,'2026 Approved Budget'!F:F) -> Buffer Role | AF39: =_xlfn.XLOOKUP($A39,'2026 Approved Budget'!$B:$B,'2026 Approved Budget'!H:H) -> 46280 | AG39: Buffer role
A40: 1048 | B40: Development | C40: 210 Clinical Operations | D40: Jaclyn Patterson | E40: FTE | F40: 08 - VP | G40: VP, Head of Clinical Operations | H40: PNJ | I40: 5 | J40: Program | K40: 2026 Q2 | L40: Open | M40: Kim | N40: BACKFILL: Brianne L. | P40: UA | Q40: Development Operations | T40: Upgraded role to VP Clin Ops | W40: 3. Upgrade | X40: 1. In line with Budget | Y40: Included In Budget (Open Role) | Z40: x | AA40: =_xlfn.XLOOKUP($A40,'2026 Approved Budget'!$B:$B,'2026 Approved Budget'!C:C) -> 210 Clinical Operations | AB40: OK | AC40: =_xlfn.XLOOKUP($A40,'2026 Approved Budget'!$B:$B,'2026 Approved Budget'!D:D) -> Brianne Leary | AD40: =_xlfn.XLOOKUP($A40,'2026 Approved Budget'!$B:$B,'2026 Approved Budget'!E:E) -> 06. Sr. Director | AE40: =_xlfn.XLOOKUP($A40,'2026 Approved Budget'!$B:$B,'2026 Approved Budget'!F:F) -> Senior Director, Development Operations | AF40: =_xlfn.XLOOKUP($A40,'2026 Approved Budget'!$B:$B,'2026 Approved Budget'!H:H) -> 45342
...

Sheet WFP Details - Beyond 2026
A1: Temp Job ID | B1: Function | C1: Department | D1: Requestor / Manager | E1: Employee Type | F1: Level | G1: Title | H1: Location | I1: Functional Priority | J1: Corp. Priority | K1: Target Start Dt | L1: Recruiting Status | M1: Recruiter | N1: Hired Name | O1: HiBob ID | P1: Asset | Q1: Key Capability | R1: Catalyst for Growth (business rationale, key deliverables, etc.) | S1: Milestone / Trigger for Hire | T1: Talent Assessment | U1: Horizon 1 | V1: Tradeoff?
A2: 5346 | B2: G&A | C2: 925 Business Development | D2: Brianne Jahn | E2: FTE | F2: 03 - Sr. Manager | G2: Senior Manager, Business Development | H2: PNJ | I2: Capacity building | K2: 2027 Q1 | P2: N/A | Q2: Financial, market, and scientific literacy—with the balance of scientific vs. financial expertise tailored to the role and shaped by the backgrounds of candidates hired into other open positions. | R2: Support the implementation of a proactive BD strategy by expanding our capacity for opportunity sourcing, strengthening CI, accelerating deal readiness, and enhancing cross-functional execution | S2: Proactive BD strategy rollout | T2: Emerging talent
A3: 5347 | B3: G&A | C3: 925 Business Development | D3: Brianne Jahn | E3: FTE | F3: 02 - Manager | G3: Manager, Business Development | H3: SSF | I3: Capacity building | K3: 2027 Q2 | P3: N/A | Q3: Scientific Literacy - ability to assess mechanisms of action, target biology, and indication relevance to support BD evaluations and cross-functional alignment | R3: Support the implementation of a proactive BD strategy by expanding our capacity for opportunity sourcing, strengthening CI, accelerating deal readiness, and enhancing cross-functional execution | S3: Proactive BD strategy rollout | T3: Emerging talent
A4: 5345 | B4: G&A | C4: 925 Business Development | D4: Brianne Jahn | E4: FTE | F4: 04 - Associate | G4: Associate or Director, Business Development | H4: SSF | I4: Capacity building | K4: 2027 Q3 | N4: Associate or director level | P4: N/A | Q4: Financial and market literacy - skilled in basic valuation, deal analysis, market research, and competitive intelligence to support strategic assessments and BD decisions | R4: Support the implementation of a proactive BD strategy by expanding our capacity for opportunity sourcing, strengthening CI, accelerating deal readiness, and enhancing cross-functional execution | S4: Proactive BD strategy rollout | T4: Extensive background in finance
A5: 5348 | B5: G&A | C5: 925 Business Development | D5: Brianne Jahn | E5: FTE | F5: 01 - Below Manager | G5: Analyst, Business Development | H5: PNJ | I5: Capacity building | K5: 2027 Q3 | P5: N/A | Q5: Financial, market, and scientific literacy—with the balance of scientific vs. financial expertise tailored to the role and shaped by the backgrounds of candidates hired into other open positions. | R5: Support the implementation of a proactive BD strategy by expanding our capacity for opportunity sourcing, strengthening CI, accelerating deal readiness, and enhancing cross-functional execution | S5: Proactive BD strategy rollout | T5: Emerging talent
A6: 1006 | B6: G&A | C6: 930 Communications | D6: Emily Faucette | E6: Agency | F6: Not Indicated | G6: IR Agency TBD | H6: SSF | K6: 2026 Q2 | L6: 2026 H1 pending insight from VP hire | N6: CW: TBD | P6: N/A | S6: Once time of IPO becomes certain
A7: 1314 | B7: G&A | C7: 930 Communications | D7: Emily Faucette | E7: Agency | F7: Not Indicated | G7: Health + Commerce | H7: SSF | K7: 2024 Q3 | L7: Onboard as of November 2024 | N7: CW: TBD | P7: N/A | Q7: Agency support and industry expertise/insights to serve as additional thought partners with capabilities to help Kardigan communications leadership execute plans - key areas of support include media relations and digital marketing | S7: Exiting stealth mode
A8: 5002 | B8: G&A | C8: 930 Communications | D8: Emily Faucette | E8: FTE | F8: (Senior) Manager | G8: Communications Manager | H8: SSF or PNJ | K8: 2027 Q1 | L8: 2026 H1 | N8: Agency support | Q8: Executional support across all communications workstreams with an emphasis on internal where more junior support is required and in-house perspective critical. Digital and social media skills a plus. | R8: As we begin to build out inmtegrated function this level hire will help us rely less on external agency support | S8: Once time of IPO becomes certain | T8: Ideally someone coming out of an agency environment who can wear many hats and is adept/thrives working in a fast-paced environment on multiple projects at once.
A9: 5220 | B9: PPM | C9: 240 PPM | D9: Amy Westfall | E9: FTE | F9: 06- Sr. Director | G9: Alliance Management | H9: SSF or PNJ | K9: 2027 Q2 | P9: N/A | Q9: Partner with GPMs to manage partnership commitmenets & milestones; build and drive capability for In-licensing/Out-licensing - develop playbooks for this | R9: Dependent on partnership activity and/or in/out-licensing activity | S9: Dependent on partnership activity and/or in/out-licensing activity
A10: 5221 | B10: PPM | C10: 240 PPM | D10: Amy Westfall/Sr Dir Alliance Management | E10: FTE | F10: 05 - Director | G10: Alliance Management | H10: SSF or PNJ | K10: 2027 Q2 | P10: N/A | Q10: Project Manage/own specific in-licensing/out-licensing activities; # of roles dependent on partnership activity | R10: Dependent on partnership activity and/or in/out-licensing activity | S10: Dependent on partnership activity and/or in/out-licensing activity
A11: 5222 | B11: PPM | C11: 240 PPM | D11: Amy Westfall/VP GPM | E11: FTE | F11: 05 - Director | G11: Global Program Manager, New Asset | H11: SSF or PNJ | K11: 2027 Q2 | P11: N/A | Q11: Program Management to drive cross-functional strategic planning, execution, risk management, resource management, and decision-making for key programs; # of roles dependent on new Asset activity | R11: Dependent on new Asset(s) within portfolio | S11: Dependent on new Asset(s) within portfolio
A12: 5223 | B12: PPM | C12: 240 PPM | D12: Amy Westfall/VP GPM | E12: FTE | F12: 04 - Assoc. Director | G12: Project Manager | H12: SSF or PNJ | K12: 2027 Q2 | P12: N/A | Q12: Addiitonal Project Management capability to support filing activities/NDA readiness | R12: Addiitonal Project Management capability to support filing activities/NDA readiness | S12: Go decisions on NDA readiness
A13: 5294 | B13: Tech Ops | C13: 410 Manufacturing | D13: Gus Kodersha | E13: FTE | F13: 05 - Director | G13: Assoc Director /Sr. Manager | H13: PNJ | I13: Business Critical | K13: 2027 Q1 | P13: Dani | Q13: DANI Program Development | S13: DANI Proc Char and Pre PPQ and NDA Authoring | T13: Technical Expert
A14: 5295 | B14: Tech Ops | C14: 410 Manufacturing | D14: Gus Kodersha | E14: FTE | F14: 04 - Assoc. Director | G14: Assoc Director /Sr. Manager | H14: PNJ | I14: Business Critical | K14: 2027 Q1 | P14: Future Asset | Q14: IND Support DS Pre-IND | S14: Pre IND DS to support IND filing | T14: Technical Expert
A15: 5296 | B15: Tech Ops | C15: 410 Manufacturing | D15: Gus Kodersha | E15: FTE | F15: 04 - Assoc. Director | G15: Assoc Director /Sr. Manager | H15: SSF | I15: Business Critical | K15: 2027 Q1 | P15: Future Asset | Q15: IND Support DS Pre-IND | S15: Pre IND DS to support IND filing | T15: Technical Expert
A16: 5300 | B16: Tech Ops | C16: 410 Manufacturing | D16: Rennan Pan | E16: FTE | F16: 05 - Director | G16: Dir/Associate Director - DP | H16: SSF | I16: Business Critical | K16: 2027 Q1 | P16: Dani | Q16: Product Development | R16: To support NDA prep for Dani; CR formulation development; New Projects | S16: FPI for Dani clinical study | T16: Technical Expert
A17: 5302 | B17: Tech Ops | C17: 410 Manufacturing | D17: Rennan Pan | E17: FTE | F17: 05 - Director | G17: Dir - DP | H17: PNJ | I17: Business Critical | K17: 2027 Q1 | P17: Future Asset | Q17: Product Development | R17: To lead drug product development for new assets | S17: Candidate selection | T17: Emerging Leader
A18: 5303 | B18: Tech Ops | C18: 410 Manufacturing | D18: Rennan Pan | E18: FTE | F18: 05 - Director | G18: Dir - DP | H18: PNJ | I18: Business Critical | K18: 2027 Q1 | P18: Future Asset | Q18: Product Development | R18: To lead drug product development for new assets | S18: In-licensing agreement signed | T18: Technical Expert
A19: 5307 | B19: Tech Ops | C19: 410 Manufacturing | D19: Leon Zhou | E19: FTE | F19: 05 - Director | G19: Director, Analytical Development | H19: PNJ | I19: Business Critical | K19: 2027 Q1 | P19: Future Asset | Q19: Analytical and Material Sciences | R19: 2G ATA and new INDs | S19: 2G ATA and new INDs | T19: Technical Expert
A20: 5310 | B20: Tech Ops | C20: 410 Manufacturing | D20: Leon Zhou | E20: FTE | F20: 04 - Assoc. Director | G20: Associate Director, Analytical Development | H20: PNJ | I20: Business Critical | K20: 2027 Q1 | P20: KAR-141 | Q20: Analytical Science | T20: Technical Expert
A21: 5314 | B21: Tech Ops | C21: 405 Supply Chain | D21: Aaron Misrack | E21: FTE | F21: 04 - Assoc. Director | G21: Associate Director, Clinical Supply Chain Planning | H21: SSF | I21: Business Critical | K21: 2027 Q1 | P21: ATA-TLA-Dani | Q21: Focused clinical planning resource to support forecasting system implementation, additional trials, new molecules and potential indications | R21: Multiple assets | S21: Organic & inorganic asset growth | T21: Technical Expert
A22: 1351 | B22: Tech Ops | C22: 405 Supply Chain | D22: Aaron Misrack | E22: FTE | F22: 04 - Assoc. Director | G22: Associate Director, Clinical Supply Chain Planning | H22: PNJ | I22: Business Critical | K22: 2027 Q1 | P22: ATA-TLA-Dani | Q22: Planning / increased modeling, ERP system implementation and ongoing oversight / use | R22: Commercial launches of multiple assets | S22: 12-18 mo ahead of first commercial launch | T22: Technical Expert
A23: 1208 | B23: Tech Ops | C23: 410 Manufacturing | D23: Erika Riffel | E23: FTE | F23: 03 - Sr. Manager | G23: Senior Manager, External Mfg. | H23: SSF | I23: Infrastructure / Support | K23: 2027 Q1 | P23: ATA-TLA-Dani | Q23: Coordinate, manage and execute the procure to pay processes & systems for Tech Ops. Replaces a consultant | R23: Multiple assets and CDMOs | S23: Volume increase and commercial launches a year out | T23: Technical Expert
A24: 5319 | B24: Tech Ops | C24: 405 Supply Chain | D24: Taylor Elkington | E24: FTE | F24: 01 - Below Manager | G24: Clinical Supply Chain Associate | H24: SSF | I24: Business Critical | K24: 2027 Q1 | P24: ATA-TLA | Q24: Clinical Supply Chain | R24: Additional indications / studies / programs | S24: Additional indications / studies / programs | T24: Technical Expert
A25: 5323 | B25: Tech Ops | C25: 405 Supply Chain | D25: Taylor Elkington | E25: FTE | F25: 03 - Sr. Manager | G25: Senior Manager, Clinical Device Supply Chain | H25: SSF | I25: Infrastructure / Support | K25: 2027 Q1 | P25: ATA-TLA-Dani | Q25: Clinical Supply Chain | R25: Prolaio kits planning, inventory management and coordination | S25: Prolaio kits planning, inventory management and coordination | T25: Technical Expert
A26: 5324 | B26: Tech Ops | C26: 405 Supply Chain | D26: Amelia Milani | E26: FTE | F26: 06 - Sr. Director | G26: Senior Director, Commercial Supply Chain | H26: SSF | I26: Business Critical | K26: 2027 Q1 | P26: ATA-TLA-Dani | Q26: Oversight of commercial SC and launch capabilities needed: 3PL, Serialization, State Licenses, Shipping Val, etc. | R26: Launches for ATA, TLA and DANI | S26: 1 year prior to NDA filing
A27: 5330 | B27: Tech Ops | C27: 410 Manufacturing | D27: William Walker | E27: FTE | F27: 03 - Sr. Manager | G27: Tech Ops Program Manager | H27: SSF | I27: Business Critical | K27: 2027 Q1 | P27: TLA | Q27: Project management within CMC / Tech Ops, owning timelines, RAID, meetings, and cross-fcungional coordination across Tech Ops | R27: Enable execution of Tech Ops operating model (meetings, timeline, actions, RAID, etc.) driven by increasing complexity of deliverables | S27: TLA Program in late-stage development | T27: Emerging Leader
A28: 5331 | B28: Tech Ops | C28: 410 Manufacturing | D28: William Walker | E28: FTE | F28: 06 - Sr. Director | G28: Tech Ops Program Lead (TOPL) | H28: PNJ | I28: Business Critical | K28: 2027 Q1 | P28: ATA-Dani | Q28: Strategic, cross-functional leadership of Tech Ops program, accountable for development, NDA readiness, risks mgmt, and EC / GPT interface | R28: Multiple and concurrent early to late stage programs requiring dedicated strategic leadership to manage cross-functional Tech Ops activities | S28: Dani Program in late-stage development | T28: Experienced Leader
A29: 5332 | B29: Tech Ops | C29: 410 Manufacturing | D29: William Walker | E29: FTE | F29: 03 - Sr. Manager | G29: Tech Ops Program Manager | H29: PNJ | I29: Business Critical | K29: 2027 Q1 | P29: Dani | Q29: Project management within CMC / Tech Ops, owning timelines, RAID, meetings, and cross-fcungional coordination across Tech Ops | R29: Enable execution of Tech Ops operating model (meetings, timeline, actions, RAID, etc.) driven by increasing complexity of deliverables | S29: Dani Program in late-stage development | T29: Emerging Leader
A30: 5335 | B30: Tech Ops | C30: 410 Manufacturing | D30: William Walker | E30: FTE | F30: 06 - Sr. Director | G30: Tech Ops Program Lead (TOPL) | H30: SSF | I30: Business Critical | K30: 2027 Q1 | P30: Future Asset | Q30: Strategic, cross-functional leadership of Tech Ops program, accountable for development, NDA readiness, risks mgmt, and EC / GPT interface | R30: Multiple and concurrent early to late stage programs requiring dedicated strategic leadership to manage cross-functional Tech Ops activities | S30: 3x early stage programs approaching IND within two to three quarters | T30: Emerging Leader
A31: 5336 | B31: Tech Ops | C31: 410 Manufacturing | D31: William Walker | E31: FTE | F31: 03 - Sr. Manager | G31: Tech Ops Program Manager | H31: SSF | I31: Infrastructure / Support | K31: 2027 Q1 | P31: Future Asset | Q31: Project management within CMC / Tech Ops, owning timelines, RAID, meetings, and cross-fcungional coordination across Tech Ops | R31: Enable execution of Tech Ops operating model (meetings, timeline, actions, RAID, etc.) driven by increasing complexity of deliverables | S31: 3x early stage programs approaching IND within two to three quarters | T31: Emerging Leader
A32: 5293 | B32: Tech Ops | C32: 410 Manufacturing | D32: Gus Kodersha | E32: FTE | F32: 04 - Assoc. Director | G32: Assoc Director /Sr. Manager | H32: SSF | I32: Business Critical | K32: 2027 Q2 | P32: TLA | Q32: TLA and ATA Program Development | S32: TLA Proc Char and Pre PPQ and NDA Authoring | T32: Technical Expert
A33: 5301 | B33: Tech Ops | C33: 410 Manufacturing | D33: Rennan Pan | E33: FTE | F33: 05 - Director | G33: Dir - DP | H33: PNJ | I33: Business Critical | K33: 2027 Q2 | P33: KAR-141 | Q33: Product Development | R33: To lead drug product development for KAR-141, process dev, CTM, TT, etc. | S33: Completion of KAR-141 POM study | T33: Emerging Leader
A34: 5309 | B34: Tech Ops | C34: 410 Manufacturing | D34: Leon Zhou | E34: FTE | F34: 04 - Assoc. Director | G34: Associate Director, Analytical Development | H34: PNJ | I34: Business Critical | K34: 2027 Q2 | P34: KAR-141 | Q34: Analytical Science/Technical Writer | R34: TLA/ATA NDAs | S34: TLA/ATA NDAs | T34: Technical Expert
A35: 5311 | B35: Tech Ops | C35: 410 Manufacturing | D35: Leon Zhou | E35: FTE | F35: 05 - Director | G35: Director, Analytical Lifecycle Management | H35: PNJ | I35: Business Critical | K35: 2027 Q2 | P35: ATA-TLA | Q35: Analytical Life Cycle | T35: Technical Expert
A36: 5312 | B36: Tech Ops | C36: 410 Manufacturing | D36: Leon Zhou | E36: FTE | F36: 03 - Sr. Manager | G36: Sr. Manager, Analytical Development | H36: SSF | I36: Business Critical | K36: 2027 Q2 | P36: Future Asset | Q36: Analytical Science | T36: Technical Expert
A37: 5313 | B37: Tech Ops | C37: 410 Manufacturing | D37: Leon Zhou | E37: FTE | F37: 03 - Sr. Manager | G37: Sr. Manager, Analytical Development | H37: SSF | I37: Business Critical | K37: 2027 Q2 | P37: Future Asset | Q37: Analytical Science | T37: Technical Expert
A38: 1198 | B38: Tech Ops | C38: 405 Supply Chain | D38: Aaron Misrack | E38: FTE | F38: 05 - Director | G38: Director, Supply Chain Planning | H38: PNJ | I38: Business Critical | K38: 2027 Q2 | P38: ATA-TLA-Dani | Q38: Planning, analytics, resilience strategy enablement | R38: Multiple assets | S38: Increasing CMO Network; SC complexity | T38: Technical Expert
A39: 5316 | B39: Tech Ops | C39: 410 Manufacturing | D39: Erika Riffel | E39: FTE | F39: 05 - Director | G39: Director, External Mfg. | H39: PNJ | I39: Business Critical | K39: 2027 Q2 | P39: ATA-TLA | Q39: Commercial CMO mgmt | R39: NDA submissions | S39: 9-12 mo ahead of NDA submission | T39: Emerging Leader
A40: 5320 | B40: Tech Ops | C40: 405 Supply Chain | D40: Taylor Elkington | E40: FTE | F40: 05 - Director | G40: Director, Clinical Supply Chain | H40: PNJ | I40: Business Critical | K40: 2027 Q2 | P40: ATA-TLA-Dani | Q40: Clinical Supply Chain | R40: OLE studies / additional indications / studies / programs | S40: OLE studies / additional indications / studies / programs | T40: Technical Expert
...

Sheet 2026 Approved Budget
H2: Subtotal | K2: =SUBTOTAL(9,K8:K1048576) -> 160 | L2: =SUBTOTAL(9,L8:L1048576) -> 160 | M2: =SUBTOTAL(9,M8:M1048576) -> 204 | N2: =SUBTOTAL(9,N8:N1048576) -> 204 | O2: =SUBTOTAL(9,O8:O1048576) -> 204 | P2: =SUBTOTAL(9,P8:P1048576) -> 224 | Q2: =SUBTOTAL(9,Q8:Q1048576) -> 224 | R2: =SUBTOTAL(9,R8:R1048576) -> 224 | ... AT2: =SUBTOTAL(9,AT8:AT1048576) -> 255
C3: Duplicate Temp Job IDs | H3: Total | K3: =SUM(K8:K1048576) -> 160 | L3: =SUM(L8:L1048576) -> 160 | M3: =SUM(M8:M1048576) -> 204 | N3: =SUM(N8:N1048576) -> 204 | O3: =SUM(O8:O1048576) -> 204 | P3: =SUM(P8:P1048576) -> 224 | Q3: =SUM(Q8:Q1048576) -> 224 | R3: =SUM(R8:R1048576) -> 224 | ... AT3: =SUM(AT8:AT1048576) -> 521
C4: 5273 / 5029 / 5357 / 5358
K5: 2026 | L5: 2026 | M5: 2026 | N5: 2026 | O5: 2026 | P5: 2026 | Q5: 2026 | R5: 2026 | S5: 2026 | T5: 2026 | U5: 2026 | V5: 2026 | W5: 2027 | X5: 2027 | Y5: 2027 | Z5: 2027 | AA5: 2027 | AB5: 2027 | AC5: 2027 | AD5: 2027 | AE5: 2027 | AF5: 2027 | AG5: 2027 | AH5: 2027 | AI5: 2028 | AJ5: 2028 | AK5: 2028 | AL5: 2028 | AM5: 2028 | AN5: 2028 | AO5: 2028 | AP5: 2028 | AQ5: 2028 | AR5: 2028 | AS5: 2028 | AT5: 2028
K6: Q1 | L6: Q1 | M6: Q1 | N6: Q2 | O6: Q2 | P6: Q2 | Q6: Q3 | R6: Q3 | S6: Q3 | T6: Q4 | U6: Q4 | V6: Q4 | W6: Q1 | X6: Q1 | Y6: Q1 | Z6: Q2 | AA6: Q2 | AB6: Q2 | AC6: Q3 | AD6: Q3 | AE6: Q3 | AF6: Q4 | AG6: Q4 | AH6: Q4 | AI6: Q1 | AJ6: Q1 | AK6: Q1 | AL6: Q2 | AM6: Q2 | AN6: Q2 | AO6: Q3 | AP6: Q3 | AQ6: Q3 | AR6: Q4 | AS6: Q4 | AT6: Q4
B7: Temp Job ID | C7: Department | D7: Employee Name | E7: Level | F7: Job title | G7: check | H7: Start Date | I7: Start Date (Month) | J7: Start Date (Year) | K7: Jan | L7: Feb | M7: Mar | N7: Apr | O7: May | P7: Jun | Q7: Jul | R7: Aug | S7: Sep | T7: Oct | U7: Nov | V7: Dec | W7: Jan | X7: Feb | Y7: Mar | Z7: Apr | AA7: May | AB7: Jun | AC7: Jul | AD7: Aug | AE7: Sep | AF7: Oct | AG7: Nov | AH7: Dec | AI7: Jan | AJ7: Feb | AK7: Mar | AL7: Apr | AM7: May | AN7: Jun | AO7: Jul | AP7: Aug | AQ7: Sep | AR7: Oct | AS7: Nov | AT7: Dec
B8: 1195 | C8: 105 Research and Translational Science | D8: Carlos del Rio | E8: 08. VP | F8: Vice President, Research and Translational Sciences | G8: =_xlfn.XLOOKUP(B8,'WFP Details - 2026'!A:A,'WFP Details - 2026'!Z:Z) -> x | H8: 45292 | I8: 1 | J8: 2024 | K8: 1 | L8: 1 | M8: 1 | N8: 1 | O8: 1 | P8: 1 | Q8: 1 | R8: 1 | S8: 1 | T8: 1 | U8: 1 | V8: 1 | W8: 1 | X8: 1 | Y8: 1 | Z8: 1 | AA8: 1 | AB8: 1 | AC8: 1 | AD8: 1 | AE8: 1 | AF8: 1 | AG8: 1 | AH8: 1 | AI8: 1 | AJ8: 1 | AK8: 1 | AL8: 1 | AM8: 1 | AN8: 1 | AO8: 1 | AP8: 1 | AQ8: 1 | AR8: 1 | AS8: 1 | AT8: 1
B9: 1192 | C9: 105 Research and Translational Science | D9: Rafael Shimkunas | E9: 03. Sr. Manager / Sr. Scientist | F9: Principal Scientist, Biology | G9: =_xlfn.XLOOKUP(B9,'WFP Details - 2026'!A:A,'WFP Details - 2026'!Z:Z) -> x | H9: 45488 | I9: 7 | J9: 2024 | K9: 1 | L9: 1 | M9: 1 | N9: 1 | O9: 1 | P9: 1 | Q9: 1 | R9: 1 | S9: 1 | T9: 1 | U9: 1 | V9: 1 | W9: 1 | X9: 1 | Y9: 1 | Z9: 1 | AA9: 1 | AB9: 1 | AC9: 1 | AD9: 1 | AE9: 1 | AF9: 1 | AG9: 1 | AH9: 1 | AI9: 1 | AJ9: 1 | AK9: 1 | AL9: 1 | AM9: 1 | AN9: 1 | AO9: 1 | AP9: 1 | AQ9: 1 | AR9: 1 | AS9: 1 | AT9: 1
